<?xml version="1.0"?>
<robot name="spot_arm">
  <link name="arm_link_sh0">
    <visual>
      <origin xyz="0 0 0" rpy="0 0 0"/>
      <geometry>
        <mesh filename="package://spot_description/meshes/arm/visual/arm_link_sh0.stl"/>
      </geometry>
      <material name="arm_link_sh0"> <color rgba="0.2 0.2 0.2 1"/></material>  
    </visual>
    <collision>
      <geometry>
        <mesh filename="package://spot_description/meshes/arm/collision/arm_link_sh0.stl" />
      </geometry>
    </collision>
    <inertial>
      <origin rpy="0.0013490340912847287 -0.15433618253071657 0.0066354181456347305" xyz="-0.012372709810733795 -4.5211403630673885e-05 -0.02103196457028389"/>
      <mass value="2.3364000000000003"/>
      <inertia ixx="0.009014303010689815" ixy="0.0" ixz="0.0" iyy="0.005835102417829581" iyz="0.0" izz="0.00778747846359954"/>
    </inertial>
  </link>
  <joint name="arm_sh0" type="revolute">
    <origin xyz="0.292 0.0 0.188" rpy="0 0 0"/>
    <axis xyz="0 0 1"/>
    <parent link="body"/>
    <child link="arm_link_sh0"/>
    <limit effort="1000" velocity="1000.00" lower="-2.61799387799149441136" upper="3.14159265358979311599"/>
  </joint>

  <link name="arm_link_sh1">
    <visual>
      <origin xyz="0 0 0" rpy="0 0 0"/>
      <geometry>
        <mesh filename="package://spot_description/meshes/arm/visual/arm_link_sh1.stl"/>
      </geometry>
      <material name="arm_link_sh1"> <color rgba="0.2 0.2 0.2 1"/></material>
    </visual>
    <collision>
      <geometry>
        <mesh filename="package://spot_description/meshes/arm/collision/arm_link_sh1.stl" />
      </geometry>
    </collision>
    <inertial>
      <origin rpy="0.009910032200701302 -0.5123007314267984 0.002209016500439809" xyz="2.4176391889341176e-05 2.4116111490002368e-06 -1.0059113265015185e-05"/>
      <mass value="0.2596"/>
      <inertia ixx="0.00020292766231464653" ixy="0.0" ixz="0.0" iyy="0.00017078637725384855" iyz="0.0" izz="0.00020384964230406682"/>
    </inertial>
  </link>
  <joint name="arm_sh1" type="revolute">
    <origin xyz="0.0 0.0 0.0" rpy="0 0 0"/>
    <axis xyz="0 1 0"/>
    <parent link="arm_link_sh0"/>
    <child link="arm_link_sh1"/>
    <!-- <limit effort="1000" velocity="1000.00" lower="-0.52359877559829881565" upper="3.14159265358979311599"/> -->
    <limit effort="1000" velocity="1000.00" lower="-3.14159265358979311599" upper="0.52359877559829881565"/>
  </joint>
  
  <link name="arm_link_hr0">
    <visual>
      <origin xyz="0 0 0" rpy="0 0 0"/>
      <geometry>
        <mesh filename="package://spot_description/meshes/arm/visual/arm_link_hr0.stl"/>
      </geometry>
      <material name="arm_link_hr0"> <color rgba="0.2 0.2 0.2 1"/></material> 
    </visual>
    <collision>
      <geometry>
        <mesh filename="package://spot_description/meshes/arm/collision/arm_link_hr0.stl" />
      </geometry>
    </collision>
    <inertial>
      <origin rpy="-0.01179850657706405 0.0002834144901480151 -0.02372295500868482" xyz="0.17047011852264404 -0.0019251034827902913 4.483893280848861e-05"/>
      <mass value="1e-06"/>
      <inertia ixx="6.312631747339145e-10" ixy="0.0" ixz="0.0" iyy="1.1487063558949979e-08" iyz="0.0" izz="1.161105128440526e-08"/>
    </inertial>
  </link>
  <joint name="arm_hr0" type="fixed">
    <origin xyz="0.0 0.0 0.0" rpy="0 0 0"/>
    <axis xyz="1 0 0"/>
    <parent link="arm_link_sh1"/>
    <child link="arm_link_hr0"/>
    <limit effort="1000" velocity="1000.00" lower="-1e6" upper="1e6"/>
  </joint>

  <link name="arm_link_el0">
    <visual>
      <origin xyz="0 0 0" rpy="0 0 0"/>
      <geometry>
        <mesh filename="package://spot_description/meshes/arm/visual/arm_link_el0.stl"/>
      </geometry>
      <material name="arm_link_el0"> <color rgba="0.2 0.2 0.2 1"/></material>  
    </visual>
    <collision>
      <geometry>
        <mesh filename="package://spot_description/meshes/arm/collision/arm_link_el0.stl" />
      </geometry>
    </collision>
    <inertial>
      <origin rpy="-0.004185887288594259 -0.6136269547775202 -0.0004619387581783485" xyz="0.0553741455078125 0.00023603376757819206 0.04827198013663292"/>
      <mass value="0.725"/>
      <inertia ixx="0.0008215365829160558" ixy="0.0" ixz="0.0" iyy="0.0020047889807066404" iyz="0.0" izz="0.0019722797759789395"/>
    </inertial>
  </link>
  <joint name="arm_el0" type="revolute">
    <origin xyz="0.3385 0 0" rpy="0 0 0"/>
    <axis xyz="0 1 0"/>
    <parent link="arm_link_hr0"/>
    <child link="arm_link_el0"/>
    <limit effort="1000" velocity="1000.00" lower="0" upper="3.14159265358979311599"/>
  </joint>

  <link name="arm_link_el1">
    <visual>
      <origin xyz="0 0 0" rpy="0 0 0"/>
      <geometry>
        <mesh filename="package://spot_description/meshes/arm/visual/arm_link_el1.stl"/>
      </geometry>
      <material name="arm_link_el1"> <color rgba="0.2 0.2 0.2 1"/></material>
    </visual>
    <collision>
      <geometry>
        <mesh filename="package://spot_description/meshes/arm/collision/arm_link_el1.stl" />
      </geometry>
    </collision>
    <inertial>
      <origin rpy="-0.15027374227250867 -0.0007874585461915551 0.003728225436950172" xyz="-0.1257835328578949 -0.013684478588402271 0.00010157923679798841"/>
      <mass value="0.725"/>
      <inertia ixx="0.0006254807525240598" ixy="0.0" ixz="0.0" iyy="0.004402454711936095" iyz="0.0" izz="0.004515915146038191"/>
    </inertial>
  </link>
  <joint name="arm_el1" type="revolute">
    <origin xyz="0.40330 0.0 0.0750" rpy="0 0 0"/>
    <axis xyz="1 0 0"/>
    <parent link="arm_link_el0"/>
    <child link="arm_link_el1"/>
    <limit effort="1000" velocity="1000.00" lower="-2.79252680319092716487" upper="2.79252680319092716487"/>
  </joint>

  <link name="arm_link_wr0">
    <visual>
      <origin xyz="0 0 0" rpy="0 0 0"/>
      <geometry>
        <mesh filename="package://spot_description/meshes/arm/visual/arm_link_wr0.stl"/>
      </geometry>
      <material name="arm_link_wr0"> <color rgba="0.2 0.2 0.2 1"/></material>
    </visual>
    <collision>
      <geometry>
        <mesh filename="package://spot_description/meshes/arm/collision/arm_link_wr0.stl" />
      </geometry>
    </collision>
    <inertial>
      <origin rpy="-0.4951534907966386 0.0033720434077784134 0.020027599337697932" xyz="0.008210677653551102 -0.012051000259816647 3.143483627354726e-05"/>
      <mass value="0.98"/>
      <inertia ixx="0.0009851320696685427" ixy="0.0" ixz="0.0" iyy="0.0008916145765810678" iyz="0.0" izz="0.0012354892751854467"/>
    </inertial>
  </link>
  <joint name="arm_wr0" type="revolute">
    <origin xyz="0.0 0.0 0.0" rpy="0 0 0"/>
    <axis xyz="0 1 0"/>
    <parent link="arm_link_el1"/>
    <child link="arm_link_wr0"/>
    <limit effort="1000" velocity="1000.00" lower="-1.83259571459404613236" upper="1.83259571459404613236"/>
  </joint>

  <link name="arm_link_wr1">
    <visual>
      <origin xyz="0 0 0" rpy="0 0 0"/>
      <geometry>
        <mesh filename="package://spot_description/meshes/arm/visual/arm_link_wr1.stl"/>
      </geometry>
      <material name="arm_link_wr1"> <color rgba="0.2 0.2 0.2 1"/></material>
    </visual>
    <collision>
      <geometry>
        <mesh filename="package://spot_description/meshes/arm/collision/arm_link_wr1.stl" />
      </geometry>
    </collision>
    <inertial>
      <origin rpy="0.006393076449033863 0.2928526604761865 -0.022814984050994802" xyz="0.12516802549362183 0.00010137435310753062 -0.013997982256114483"/>
      <mass value="0.785"/>
      <inertia ixx="0.00076741362048185" ixy="0.0" ixz="0.0" iyy="0.0017628124054271809" iyz="0.0" izz="0.0016818105865345951"/>
    </inertial>
  </link>
  <joint name="arm_wr1" type="revolute">
    <origin xyz="0.0 0.0 0.0" rpy="0 0 0"/>
    <axis xyz="1 0 0"/>
    <parent link="arm_link_wr0"/>
    <child link="arm_link_wr1"/>
    <limit effort="1000" velocity="1000.00" lower="-2.87979326579064354163" upper="2.87979326579064354163"/>
  </joint>
  
  <link name="arm_link_fngr">
    <visual>
      <origin xyz="0 0 0" rpy="0 0 0"/>
      <geometry>
        <mesh filename="package://spot_description/meshes/arm/visual/arm_link_fngr.stl"/>
      </geometry>
      <material name="arm_link_fngr"> <color rgba="0.2 0.2 0.2 1"/></material>
    </visual>
    <collision>
      <geometry>
        <mesh filename="package://spot_description/meshes/arm/collision/arm_link_fngr.stl" />
      </geometry>
    </collision>
    <inertial>
      <origin rpy="0.0003416659657240473 0.3751670012784243 -0.004058661249495721" xyz="0.04787873849272728 -0.00020676758140325546 -0.01628788933157921"/>
      <mass value="0.2"/>
      <inertia ixx="0.0001439963634171048" ixy="0.0" ixz="0.0" iyy="0.0003007126997998294" iyz="0.0" izz="0.0003912783268020657"/>
    </inertial>
  </link>
  <joint name="arm_f1x" type="revolute">
    <origin xyz="0.11745 0 0.014820" rpy="0 0 0"/>
    <axis xyz="0.0 1.0 0.0"/>
    <parent link="arm_link_wr1"/>
    <child link="arm_link_fngr"/>
    <limit effort="1000" velocity="1000.00" lower="-1.57" upper="0.0"/>
  </joint>
</robot>
