<?xml version="1.0" ?>
<!-- =================================================================================== -->
<!-- |    This document was autogenerated by xacro from puma560_robot.urdf.xacro       | -->
<!-- |    EDITING THIS FILE BY HAND IS NOT RECOMMENDED                                 | -->
<!-- =================================================================================== -->
<robot name="Puma560" xmlns:xacro="http://www.ros.org/wiki/xacro">
  <material name="blue">
    <color rgba="0 0 0.8 0.8"/>
  </material>
  <material name="red">
    <color rgba="0.8 0 0 0.8"/>
  </material>
  <material name="green">
    <color rgba="0 0.8 0 0.8"/>
  </material>
  <!-- DH Paramaters -->
  <link name="link1">
    <visual>
      <geometry>
        <mesh filename="package://puma560_description/meshes/puma_link1.stl" scale="0.0254 0.0254 0.0254"/>
      </geometry>
      <origin rpy="0 0 1.570796325"/>
      <material name="green"/>
    </visual>
  </link>
  <link name="link2">
    <visual>
      <geometry>
        <mesh filename="package://puma560_description/meshes/puma_link2.stl" scale="0.0254 0.0254 0.0254"/>
      </geometry>
      <origin rpy="0 0 0" xyz="0 0 -0.1"/>
      <material name="red"/>
    </visual>
  </link>
  <joint name="j1" type="revolute">
    <parent link="link1"/>
    <child link="link2"/>
    <origin rpy="1.570796325 0 0" xyz="0 0 0.6718"/>
    <axis xyz="0 1 0"/>
    <!-- This is descibed in child frame -->
    <limit effort="1000.0" lower="-3.14159265" upper="3.14159265" velocity="0"/>
  </joint>
  <link name="link3">
    <visual>
      <geometry>
        <mesh filename="package://puma560_description/meshes/puma_link3.stl" scale="0.0254 0.0254 0.0254"/>
      </geometry>
      <origin xyz="0 0 0.1936"/>
      <material name="blue"/>
    </visual>
  </link>
  <joint name="j2" type="revolute">
    <parent link="link2"/>
    <child link="link3"/>
    <origin rpy="0 0 0" xyz="0 0 0"/>
    <axis xyz="0 0 1"/>
    <!-- This is descibed in child frame -->
    <limit effort="1000.0" lower="-1.570796325" upper="1.570796325" velocity="0"/>
  </joint>
  <link name="link4">
    <visual>
      <geometry>
        <mesh filename="package://puma560_description/meshes/puma_link4.stl" scale="0.0254 0.0254 0.0254"/>
      </geometry>
      <origin rpy="0 0 0" xyz="0 0 0"/>
      <material name="green"/>
    </visual>
  </link>
  <joint name="j3" type="revolute">
    <parent link="link3"/>
    <child link="link4"/>
    <origin rpy="0 0 -1.570796325" xyz="0.4318 -0.0203 0.1501"/>
    <axis xyz="0 0 1"/>
    <!-- This is descibed in child frame -->
    <limit effort="1000.0" lower="-1.570796325" upper="1.570796325" velocity="0"/>
  </joint>
  <link name="link5">
    <visual>
      <geometry>
        <mesh filename="package://puma560_description/meshes/puma_link5.stl" scale="0.0254 0.0254 0.0254"/>
      </geometry>
      <origin rpy="0 0 1.570796325" xyz="0 0 0.3621"/>
      <material name="red"/>
    </visual>
  </link>
  <joint name="j4" type="revolute">
    <parent link="link4"/>
    <child link="link5"/>
    <origin rpy="1.570796325 0 1.570796325" xyz="0 0 0"/>
    <axis xyz="0 0 1"/>
    <limit effort="1000.0" lower="-1.570796325" upper="1.570796325" velocity="0"/>
  </joint>
  <link name="link6">
    <visual>
      <geometry>
        <mesh filename="package://puma560_description/meshes/puma_link6.stl" scale="0.0254 0.0254 0.0254"/>
      </geometry>
      <origin rpy="3.14159265 0 1.570796325" xyz="0 0 0"/>
      <material name="green"/>
    </visual>
  </link>
  <joint name="j5" type="revolute">
    <parent link="link5"/>
    <child link="link6"/>
    <origin rpy="1.570796325 0 0" xyz="0 0 0.4331"/>
    <axis xyz="0 0 1"/>
    <limit effort="1000.0" lower="-1.570796325" upper="1.570796325" velocity="0"/>
  </joint>
  <link name="link7">
    <visual>
      <geometry>
        <mesh filename="package://puma560_description/meshes/puma_link7.stl" scale="0.0254 0.0254 0.0254"/>
      </geometry>
      <origin rpy="0 0 0" xyz="0 0 -0.010"/>
      <material name="blue"/>
    </visual>
  </link>
  <joint name="j6" type="revolute">
    <parent link="link6"/>
    <child link="link7"/>
    <origin rpy="-1.570796325 0 0" xyz="0 0.0558 0"/>
    <axis xyz="0 0 1"/>
    <limit effort="1000.0" lower="-1.570796325" upper="1.570796325" velocity="0"/>
  </joint>
</robot>

