<?xml version="1.0"?>

<robot name="gen3_arm" xmlns:xacro="http://ros.org/wiki/xacro">

  <!-- Propagate last link name information because it is the gripper's parent link -->
  <xacro:property name="last_arm_link" value="end_effector_link"/>

  <xacro:macro name="load_arm" params="parent:='' dof vision prefix *origin">
    <link name="${prefix}base_link">
      <inertial>
        <origin xyz="-0.000648 -0.000166 0.084487" rpy="0 0 0" />
        <mass value="1.697" />
        <inertia ixx="0.004622" ixy="9E-06" ixz="6E-05" iyy="0.004495" iyz="9E-06" izz="0.002079" />
      </inertial>
      <visual>
        <origin xyz="0 0 0" rpy="0 0 0" />
        <geometry>
          <mesh filename="package://kortex_description/arms/gen3/${dof}dof/meshes/base_link.STL" />
        </geometry>
        <material name="">
          <color rgba="0.75294 0.75294 0.75294 1" />
        </material>
      </visual>
      <collision>
        <origin xyz="0 0 0" rpy="0 0 0" />
        <geometry>
          <mesh filename="package://kortex_description/arms/gen3/${dof}dof/meshes/base_link.STL" />
        </geometry>
      </collision>
    </link>
    <link name="${prefix}shoulder_link">
      <inertial>
        <origin xyz="-2.3E-05 -0.010364 -0.07336" rpy="0 0 0" />
        <mass value="1.377" />
        <inertia ixx="0.00457" ixy="1E-06" ixz="2E-06" iyy="0.004831" iyz="0.000448" izz="0.001409" />
      </inertial>
      <visual>
        <origin xyz="0 0 0" rpy="0 0 0" />
        <geometry>
          <mesh filename="package://kortex_description/arms/gen3/${dof}dof/meshes/shoulder_link.STL" />
        </geometry>
        <material name="">
          <color rgba="0.75294 0.75294 0.75294 1" />
        </material>
      </visual>
      <collision>
        <origin xyz="0 0 0" rpy="0 0 0" />
        <geometry>
          <mesh filename="package://kortex_description/arms/gen3/${dof}dof/meshes/shoulder_link.STL" />
        </geometry>
      </collision>
    </link>
    <joint name="${prefix}joint_1" type="continuous">
      <origin xyz="0 0 0.15643" rpy="-3.1416 0.0 0.0" />
      <parent link="${prefix}base_link" />
      <child link="${prefix}shoulder_link" />
      <axis xyz="0 0 1" />
      <limit effort="39" velocity="1.3963" />
    </joint>
    <link name="${prefix}bicep_link">
      <inertial>
        <origin xyz="3.5E-05 -0.208207 -0.01889" rpy="0 0 0" />
        <mass value="1.262" />
        <inertia ixx="0.046752" ixy="-9E-06" ixz="0" iyy="0.00085" iyz="-9.8E-05" izz="0.047188" />
      </inertial>
      <visual>
        <origin xyz="0 0 0" rpy="0 0 0" />
        <geometry>
          <mesh filename="package://kortex_description/arms/gen3/${dof}dof/meshes/bicep_link.STL" />
        </geometry>
        <material name="">
          <color rgba="0.75294 0.75294 0.75294 1" />
        </material>
      </visual>
      <collision>
        <origin xyz="0 0 0" rpy="0 0 0" />
        <geometry>
          <mesh filename="package://kortex_description/arms/gen3/${dof}dof/meshes/bicep_link.STL" />
        </geometry>
      </collision>
    </link>
    <joint name="${prefix}joint_2" type="revolute">
      <origin xyz="0 0.005375 -0.12838" rpy="1.5708 0.0 0.0" />
      <parent link="${prefix}shoulder_link" />
      <child link="${prefix}bicep_link" />
      <axis xyz="0 0 1" />
      <limit lower="-2.41" upper="2.41" effort="39" velocity="1.3963" />
    </joint>
    <link name="${prefix}forearm_link">
      <inertial>
        <origin xyz="1.8E-05 0.076168 -0.01397" rpy="0 0 0" />
        <mass value="0.93" />
        <inertia ixx="0.008292" ixy="-1E-06" ixz="0" iyy="0.000628" iyz="0.000432" izz="0.008464" />
      </inertial>
      <visual>
        <origin xyz="0 0 0" rpy="0 0 0" />
        <geometry>
          <mesh filename="package://kortex_description/arms/gen3/${dof}dof/meshes/forearm_link.STL" />
        </geometry>
        <material name="">
          <color rgba="0.75294 0.75294 0.75294 1" />
        </material>
      </visual>
      <collision>
        <origin xyz="0 0 0" rpy="0 0 0" />
        <geometry>
          <mesh filename="package://kortex_description/arms/gen3/${dof}dof/meshes/forearm_link.STL" />
        </geometry>
      </collision>
    </link>
    <joint name="${prefix}joint_3" type="revolute">
      <origin xyz="0 -0.41 0" rpy="3.1416 0 0" />
      <parent link="${prefix}bicep_link" />
      <child link="${prefix}forearm_link" />
      <axis xyz="0 0 1" />
      <limit lower="-2.66" upper="2.66" effort="39" velocity="1.3963" />
    </joint>
    <link name="${prefix}spherical_wrist_1_link">
      <inertial>
        <origin xyz="-1E-06 0.008486 -0.062937" rpy="0 0 0" />
        <mass value="0.6781" />
        <inertia ixx="0.001645" ixy="0" ixz="0" iyy="0.001666" iyz="-0.000234" izz="0.000389" />
      </inertial>
      <visual>
        <origin xyz="0 0 0" rpy="0 0 0" />
        <geometry>
          <mesh filename="package://kortex_description/arms/gen3/${dof}dof/meshes/spherical_wrist_1_link.STL" />
        </geometry>
        <material name="">
          <color rgba="0.75294 0.75294 0.75294 1" />
        </material>
      </visual>
      <collision>
        <origin xyz="0 0 0" rpy="0 0 0" />
        <geometry>
          <mesh filename="package://kortex_description/arms/gen3/${dof}dof/meshes/spherical_wrist_1_link.STL" />
        </geometry>
      </collision>
    </link>
    <joint name="${prefix}joint_4" type="continuous">
      <origin xyz="0 0.20843 -0.006375" rpy="1.5708 0.0 0.0" />
      <parent link="${prefix}forearm_link" />
      <child link="${prefix}spherical_wrist_1_link" />
      <axis xyz="0 0 1" />
      <limit effort="9" velocity="1.2218" />
    </joint>
    <link name="${prefix}spherical_wrist_2_link">
      <inertial>
        <origin xyz="-1E-06 0.046429 -0.008704" rpy="0 0 0" />
        <mass value="0.678" />
        <inertia ixx="0.001685" ixy="0" ixz="0" iyy="0.0004" iyz="0.000255" izz="0.001696" />
      </inertial>
      <visual>
        <origin xyz="0 0 0" rpy="0 0 0" />
        <geometry>
          <mesh filename="package://kortex_description/arms/gen3/${dof}dof/meshes/spherical_wrist_2_link.STL" />
        </geometry>
        <material name="">
          <color rgba="0.75294 0.75294 0.75294 1" />
        </material>
      </visual>
      <collision>
        <origin xyz="0 0 0" rpy="0 0 0" />
        <geometry>
          <mesh filename="package://kortex_description/arms/gen3/${dof}dof/meshes/spherical_wrist_2_link.STL" />
        </geometry>
      </collision>
    </link>
    <joint name="${prefix}joint_5" type="revolute">
      <origin xyz="0 -0.00017505 -0.10593" rpy="-1.5708 0.0 0.0" />
      <parent link="${prefix}spherical_wrist_1_link" />
      <child link="${prefix}spherical_wrist_2_link" />
      <axis xyz="0 0 1" />
      <limit lower="-2.23" upper="2.23" effort="9" velocity="1.2218" />
    </joint>
    <xacro:if value="${vision}">
    <link name="${prefix}bracelet_link">
      <inertial>
        <origin xyz="0.000281 0.011402 -0.029798" rpy="0 0 0" />
        <mass value="0.5" />
        <inertia ixx="0.000587" ixy="3E-06" ixz="3E-06" iyy="0.000369" iyz="-0.000118" izz="0.000609" />
      </inertial>
      <visual>
        <origin xyz="0 0 0" rpy="0 0 0" />
        <geometry>
          <mesh filename="package://kortex_description/arms/gen3/${dof}dof/meshes/bracelet_with_vision_link.STL" />
        </geometry>
        <material name="">
          <color rgba="0.75294 0.75294 0.75294 1" />
        </material>
      </visual>
      <collision>
        <origin xyz="0 0 0" rpy="0 0 0" />
        <geometry>
          <mesh filename="package://kortex_description/arms/gen3/${dof}dof/meshes/bracelet_with_vision_link.STL" />
        </geometry>
      </collision>
    </link>
    </xacro:if>
    <xacro:unless value="${vision}">
    <link name="${prefix}bracelet_link">
      <inertial>
        <origin xyz="-9.3E-05 0.000132 -0.022905" rpy="0 0 0" />
        <mass value="0.364" />
        <inertia ixx="0.000214" ixy="0" ixz="1E-06" iyy="0.000223" iyz="-2E-06" izz="0.00024" />
      </inertial>
      <visual>
        <origin xyz="0 0 0" rpy="0 0 0" />
        <geometry>
          <mesh filename="package://kortex_description/arms/gen3/${dof}dof/meshes/bracelet_no_vision_link.STL" />
        </geometry>
        <material name="">
          <color rgba="0.75294 0.75294 0.75294 1" />
        </material>
      </visual>
      <collision>
        <origin xyz="0 0 0" rpy="0 0 0" />
        <geometry>
          <mesh filename="package://kortex_description/arms/gen3/${dof}dof/meshes/bracelet_no_vision_link.STL" />
        </geometry>
      </collision>
    </link>
    </xacro:unless>
    <joint name="${prefix}joint_6" type="continuous">
      <origin xyz="0 0.10593 -0.00017505" rpy="1.5708 0.0 0.0" />
      <parent link="${prefix}spherical_wrist_2_link" />
      <child link="${prefix}bracelet_link" />
      <axis xyz="0 0 1" />
      <limit effort="9" velocity="1.2218" />
    </joint>
    <link name="${prefix}end_effector_link" />
    <joint
      name="${prefix}end_effector"
      type="fixed">
      <origin xyz="0 0 -0.0615250000000001" rpy="3.14159265358979 1.09937075168372E-32 3.14159265358979" />
      <parent
        link="${prefix}bracelet_link" />
      <child
        link="${prefix}end_effector_link" />
      <axis
        xyz="0 0 0" />
    </joint>
  </xacro:macro>
</robot>
