<robot name="GEN3-6DOF_VISION_URDF_ARM_V01" version="1.0">
  <link name="Base_Link">
    <inertial>
      <origin xyz="-0.000648 -0.000166 0.084487" rpy="0 0 0" />
      <mass value="1.697" />
      <inertia ixx="0.004622" ixy="9E-06" ixz="6E-05" iyy="0.004495" iyz="9E-06" izz="0.002079" />
    </inertial>
    <visual>
      <origin xyz="0 0 0" rpy="0 0 0" />
      <geometry>
        <mesh filename="package://kortex_description/arms/gen3/6dof/meshes/base_link.STL" />
      </geometry>
      <material name="">
        <color rgba="0.75294 0.75294 0.75294 1" />
      </material>
    </visual>
    <collision>
      <origin xyz="0 0 0" rpy="0 0 0" />
      <geometry>
        <mesh filename="package://kortex_description/arms/gen3/6dof/meshes/base_link.STL" />
      </geometry>
    </collision>
  </link>
  <link name="Shoulder_Link">
    <inertial>
      <origin xyz="-2.3E-05 -0.010364 -0.07336" rpy="0 0 0" />
      <mass value="1.377" />
      <inertia ixx="0.00457" ixy="1E-06" ixz="2E-06" iyy="0.004831" iyz="0.000448" izz="0.001409" />
    </inertial>
    <visual>
      <origin xyz="0 0 0" rpy="0 0 0" />
      <geometry>
        <mesh filename="package://kortex_description/arms/gen3/6dof/meshes/shoulder_link.STL" />
      </geometry>
      <material name="">
        <color rgba="0.75294 0.75294 0.75294 1" />
      </material>
    </visual>
    <collision>
      <origin xyz="0 0 0" rpy="0 0 0" />
      <geometry>
        <mesh filename="package://kortex_description/arms/gen3/6dof/meshes/shoulder_link.STL" />
      </geometry>
    </collision>
  </link>
  <joint name="Actuator1" type="continuous">
    <origin xyz="0 0 0.15643" rpy="-3.1416 0.0 0.0" />
    <parent link="Base_Link" />
    <child link="Shoulder_Link" />
    <axis xyz="0 0 1" />
    <limit effort="39" velocity="0.8727" />
  </joint>
  <link name="Bicep_Link">
    <inertial>
      <origin xyz="3.5E-05 -0.208207 -0.01889" rpy="0 0 0" />
      <mass value="1.262" />
      <inertia ixx="0.046752" ixy="-9E-06" ixz="0" iyy="0.00085" iyz="-9.8E-05" izz="0.047188" />
    </inertial>
    <visual>
      <origin xyz="0 0 0" rpy="0 0 0" />
      <geometry>
        <mesh filename="package://kortex_description/arms/gen3/6dof/meshes/bicep_link.STL" />
      </geometry>
      <material name="">
        <color rgba="0.75294 0.75294 0.75294 1" />
      </material>
    </visual>
    <collision>
      <origin xyz="0 0 0" rpy="0 0 0" />
      <geometry>
        <mesh filename="package://kortex_description/arms/gen3/6dof/meshes/bicep_link.STL" />
      </geometry>
    </collision>
  </link>
  <joint name="Actuator2" type="revolute">
    <origin xyz="0 0.005375 -0.12838" rpy="1.5708 0.0 0.0" />
    <parent link="Shoulder_Link" />
    <child link="Bicep_Link" />
    <axis xyz="0 0 1" />
    <limit lower="-2.41" upper="2.41" effort="39" velocity="0.8727" />
  </joint>
  <link name="ForeArm_Link">
    <inertial>
      <origin xyz="1.8E-05 0.076168 -0.01397" rpy="0 0 0" />
      <mass value="0.93" />
      <inertia ixx="0.008292" ixy="-1E-06" ixz="0" iyy="0.000628" iyz="0.000432" izz="0.008464" />
    </inertial>
    <visual>
      <origin xyz="0 0 0" rpy="0 0 0" />
      <geometry>
        <mesh filename="package://kortex_description/arms/gen3/6dof/meshes/forearm_link.STL" />
      </geometry>
      <material name="">
        <color rgba="0.75294 0.75294 0.75294 1" />
      </material>
    </visual>
    <collision>
      <origin xyz="0 0 0" rpy="0 0 0" />
      <geometry>
        <mesh filename="package://kortex_description/arms/gen3/6dof/meshes/forearm_link.STL" />
      </geometry>
    </collision>
  </link>
  <joint name="Actuator3" type="revolute">
    <origin xyz="0 -0.41 0" rpy="3.1416 0 0" />
    <parent link="Bicep_Link" />
    <child link="ForeArm_Link" />
    <axis xyz="0 0 1" />
    <limit lower="-2.66" upper="2.66" effort="39" velocity="0.8727" />
  </joint>
  <link name="SphericalWrist1_Link">
    <inertial>
      <origin xyz="-1E-06 0.008486 -0.062937" rpy="0 0 0" />
      <mass value="0.6781" />
      <inertia ixx="0.001645" ixy="0" ixz="0" iyy="0.001666" iyz="-0.000234" izz="0.000389" />
    </inertial>
    <visual>
      <origin xyz="0 0 0" rpy="0 0 0" />
      <geometry>
        <mesh filename="package://kortex_description/arms/gen3/6dof/meshes/spherical_wrist_1_link.STL" />
      </geometry>
      <material name="">
        <color rgba="0.75294 0.75294 0.75294 1" />
      </material>
    </visual>
    <collision>
      <origin xyz="0 0 0" rpy="0 0 0" />
      <geometry>
        <mesh filename="package://kortex_description/arms/gen3/6dof/meshes/spherical_wrist_1_link.STL" />
      </geometry>
    </collision>
  </link>
  <joint name="Actuator4" type="continuous">
    <origin xyz="0 0.20843 -0.006375" rpy="1.5708 0.0 0.0" />
    <parent link="ForeArm_Link" />
    <child link="SphericalWrist1_Link" />
    <axis xyz="0 0 1" />
    <limit effort="9" velocity="0.8727" />
  </joint>
  <link name="SphericalWrist2_Link">
    <inertial>
      <origin xyz="-1E-06 0.046429 -0.008704" rpy="0 0 0" />
      <mass value="0.678" />
      <inertia ixx="0.001685" ixy="0" ixz="0" iyy="0.0004" iyz="0.000255" izz="0.001696" />
    </inertial>
    <visual>
      <origin xyz="0 0 0" rpy="0 0 0" />
      <geometry>
        <mesh filename="package://kortex_description/arms/gen3/6dof/meshes/spherical_wrist_2_link.STL" />
      </geometry>
      <material name="">
        <color rgba="0.75294 0.75294 0.75294 1" />
      </material>
    </visual>
    <collision>
      <origin xyz="0 0 0" rpy="0 0 0" />
      <geometry>
        <mesh filename="package://kortex_description/arms/gen3/6dof/meshes/spherical_wrist_2_link.STL" />
      </geometry>
    </collision>
  </link>
  <joint name="Actuator5" type="revolute">
    <origin xyz="0 -0.00017505 -0.10593" rpy="-1.5708 0.0 0.0" />
    <parent link="SphericalWrist1_Link" />
    <child link="SphericalWrist2_Link" />
    <axis xyz="0 0 1" />
    <limit lower="-2.23" upper="2.23" effort="9" velocity="0.8727" />
  </joint>
  <link name="Bracelet_Link">
    <inertial>
      <origin xyz="0.000281 0.011402 -0.029798" rpy="0 0 0" />
      <mass value="0.5" />
      <inertia ixx="0.000587" ixy="3E-06" ixz="3E-06" iyy="0.000369" iyz="-0.000118" izz="0.000609" />
    </inertial>
    <visual>
      <origin xyz="0 0 0" rpy="0 0 0" />
      <geometry>
        <mesh filename="package://kortex_description/arms/gen3/6dof/meshes/bracelet_with_vision_link.STL" />
      </geometry>
      <material name="">
        <color rgba="0.75294 0.75294 0.75294 1" />
      </material>
    </visual>
    <collision>
      <origin xyz="0 0 0" rpy="0 0 0" />
      <geometry>
        <mesh filename="package://kortex_description/arms/gen3/6dof/meshes/bracelet_with_vision_link.STL" />
      </geometry>
    </collision>
  </link>
  <joint name="Actuator6" type="continuous">
    <origin xyz="0 0.10593 -0.00017505" rpy="1.5708 0.0 0.0" />
    <parent link="SphericalWrist2_Link" />
    <child link="Bracelet_Link" />
    <axis xyz="0 0 1" />
    <limit effort="9" velocity="0.8727" />
  </joint>
  <link name="EndEffector_Link">
    <inertial>
      <origin xyz="0 0 0" rpy="0 0 0" />
      <mass value="0" />
      <inertia ixx="0" ixy="0" ixz="0" iyy="0" iyz="0" izz="0" />
    </inertial>
    <visual>
      <origin xyz="0 0 0" rpy="0 0 0" />
      <geometry>
        <mesh filename="package://kortex_description/arms/gen3/6dof/meshes/EndEffector_Link.STL" />
      </geometry>
      <material name="">
        <color rgba="0.75294 0.75294 0.75294 1" />
      </material>
    </visual>
    <collision>
      <origin xyz="0 0 0" rpy="0 0 0" />
      <geometry>
        <mesh filename="package://kortex_description/arms/gen3/6dof/meshes/EndEffector_Link.STL" />
      </geometry>
    </collision>
  </link>
  <joint name="EndEffector" type="fixed">
    <origin xyz="0 0 -0.061525" rpy="3.1416 0 -3.1416" />
    <parent link="Bracelet_Link" />
    <child link="EndEffector_Link" />
    <axis xyz="0 0 0" />
  </joint>
</robot>