<?xml version="1.0"?>
<robot name="rx200" xmlns:xacro="http://ros.org/wiki/xacro">

  <xacro:arg name="robot_name" default = ""/>
  <xacro:arg name="use_world_frame" default="false"/>
  <xacro:arg name="use_default_gripper_bar" default="true"/>
  <xacro:arg name="use_default_gripper_fingers" default="true"/>
  <xacro:arg name="external_urdf_loc" default=""/>
  <xacro:arg name="load_gazebo_configs" default="false"/>

  <xacro:property name="urdf_loc" value="$(arg external_urdf_loc)"/>

  <xacro:if value="$(arg load_gazebo_configs)">
    <xacro:include filename="$(find interbotix_gazebo)/config/interbotix_texture.gazebo"/>
  </xacro:if>

  <material name="interbotix_black">
    <texture filename="package://interbotix_descriptions/meshes/interbotix_black.png"/>
  </material>

  <xacro:if value="$(arg use_world_frame)">
    <link name="world"/>
    <joint name="fixed" type="fixed">
      <parent link="world"/>
      <child link="$(arg robot_name)/base_link"/>
    </joint>
  </xacro:if>

  <link name="$(arg robot_name)/base_link">
    <visual>
      <origin rpy="0 0 ${-pi/2}" xyz="0 0 0"/>
      <geometry>
        <mesh filename="package://interbotix_descriptions/meshes/meshes_rx200/RXA-200-M-1-Base.stl" scale="0.001 0.001 0.001"/>
      </geometry>
      <material name="interbotix_black"/>
    </visual>
    <collision>
      <origin rpy="0 0 ${-pi/2}" xyz="0 0 0"/>
      <geometry>
        <mesh filename="package://interbotix_descriptions/meshes/meshes_rx200/RXA-200-M-1-Base.stl" scale="0.001 0.001 0.001"/>
      </geometry>
    </collision>
    <inertial>
      <origin rpy="0 0 ${pi/2}" xyz="-0.0354389000 -0.0033586100 0.0253408000"/>
      <mass value="0.766135" />
      <inertia ixx="0.0033530000" iyy="0.0013570000" izz="0.0041110000" ixy="-0.0001246000" ixz="0.0000110600" iyz="0.0002103000" />
    </inertial>
  </link>

  <joint name="waist" type="revolute">
    <axis xyz="0 0 1"/>
    <limit effort="100" lower="${-pi}" upper="${pi}" velocity="${pi}"/>
    <origin rpy="0 0 0" xyz="0 0 0.065"/>
    <parent link="$(arg robot_name)/base_link"/>
    <child link="$(arg robot_name)/shoulder_link"/>
  </joint>

  <transmission name="trans_waist">
    <type>transmission_interface/SimpleTransmission</type>
    <joint name="waist">
      <hardwareInterface>hardware_interface/EffortJointInterface</hardwareInterface>
    </joint>
    <actuator name="waist_motor">
      <mechanicalReduction>1</mechanicalReduction>
    </actuator>
  </transmission>

  <link name="$(arg robot_name)/shoulder_link">
    <visual>
      <origin rpy="0 0 ${-pi/2}" xyz="0 0 0.0015"/>
      <geometry>
        <mesh filename="package://interbotix_descriptions/meshes/meshes_rx200/RXA-200-M-2-Shoulder.stl" scale="0.001 0.001 0.001"/>
      </geometry>
      <material name="interbotix_black"/>
    </visual>
    <collision>
      <origin rpy="0 0 ${-pi/2}" xyz="0 0 0.0015"/>
      <geometry>
        <mesh filename="package://interbotix_descriptions/meshes/meshes_rx200/RXA-200-M-2-Shoulder.stl" scale="0.001 0.001 0.001"/>
      </geometry>
    </collision>
    <inertial>
      <origin rpy="0 0 ${pi/2}" xyz="-0.0000853644 0.0000173690 0.0132005000"/>
      <mass value="0.257774" />
      <inertia ixx="0.0002663000" iyy="0.0004428000" izz="0.0004711000" ixy="0.0000000009" ixz="0.0000000511" iyz="0.0000004416" />
    </inertial>
  </link>

  <joint name="shoulder" type="revolute">
    <axis xyz="0 1 0"/>
    <limit effort="100" lower="${radians(-107)}" upper="${radians(111)}" velocity="1"/>
    <origin rpy="0 0 0" xyz="0 0 0.03891"/>
    <parent link="$(arg robot_name)/shoulder_link"/>
    <child link="$(arg robot_name)/upper_arm_link"/>
  </joint>

  <transmission name="trans_shoulder">
    <type>transmission_interface/SimpleTransmission</type>
    <joint name="shoulder">
      <hardwareInterface>hardware_interface/EffortJointInterface</hardwareInterface>
    </joint>
    <actuator name="shoulder_motor">
      <mechanicalReduction>1</mechanicalReduction>
    </actuator>
  </transmission>

  <link name="$(arg robot_name)/upper_arm_link">
    <visual>
      <origin rpy="0 0 ${pi/2}" xyz="0 0 0"/>
      <geometry>
        <mesh filename="package://interbotix_descriptions/meshes/meshes_rx200/RXA-200-M-3-UA.stl" scale="0.001 0.001 0.001"/>
      </geometry>
      <material name="interbotix_black"/>
    </visual>
    <collision>
      <origin rpy="0 0 ${pi/2}" xyz="0 0 0"/>
      <geometry>
        <mesh filename="package://interbotix_descriptions/meshes/meshes_rx200/RXA-200-M-3-UA.stl" scale="0.001 0.001 0.001"/>
      </geometry>
    </collision>
    <inertial>
      <origin rpy="0 0 ${pi/2}" xyz="0.0119513000 -0.0001169230 0.1394300000"/>
      <mass value="0.297782" />
      <inertia ixx="0.0017100000" iyy="0.0016310000" izz="0.0001478000" ixy="-0.0000009773" ixz="0.0000020936" iyz="0.0002132000" />
    </inertial>
  </link>

  <joint name="elbow" type="revolute">
    <axis xyz="0 1 0"/>
    <limit effort="100" lower="${radians(-93)}" upper="${radians(108)}" velocity="${pi}"/>
    <origin rpy="${pi} 0 0" xyz="0.05 0 0.2"/>
    <parent link="$(arg robot_name)/upper_arm_link"/>
    <child link="$(arg robot_name)/forearm_link"/>
  </joint>

  <transmission name="trans_elbow">
    <type>transmission_interface/SimpleTransmission</type>
    <joint name="elbow">
      <hardwareInterface>hardware_interface/EffortJointInterface</hardwareInterface>
    </joint>
    <actuator name="elbow_motor">
      <mechanicalReduction>1</mechanicalReduction>
    </actuator>
  </transmission>

  <link name="$(arg robot_name)/forearm_link">
    <visual>
      <origin rpy="0 0 ${pi/2}" xyz="0 0 0"/>
      <geometry>
        <mesh filename="package://interbotix_descriptions/meshes/meshes_rx200/RXA-200-M-4-Forearm.stl" scale="0.001 0.001 0.001"/>
      </geometry>
      <material name="interbotix_black"/>
    </visual>
    <collision>
      <origin rpy="0 0 ${pi/2}" xyz="0 0 0"/>
      <geometry>
        <mesh filename="package://interbotix_descriptions/meshes/meshes_rx200/RXA-200-M-4-Forearm.stl" scale="0.001 0.001 0.001"/>
      </geometry>
    </collision>
    <inertial>
      <origin rpy="0 0 ${pi/2}" xyz="0.1147450000 -0.0000938376 0.0000000000"/>
      <mass value="0.258863" />
      <inertia ixx="0.0010550000" iyy="0.0000642100" izz="0.0010760000" ixy="-0.0000018286" ixz="0.0000000000" iyz="0.0000000000" />
    </inertial>
  </link>

  <joint name="wrist_angle" type="revolute">
    <axis xyz="0 1 0"/>
    <limit effort="100" lower="${radians(-123)}" upper="${radians(100)}" velocity="${pi}"/>
    <origin rpy="0 0 0" xyz="0.2 0 0"/>
    <parent link="$(arg robot_name)/forearm_link"/>
    <child link="$(arg robot_name)/wrist_link"/>
  </joint>

  <transmission name="trans_wrist_angle">
    <type>transmission_interface/SimpleTransmission</type>
    <joint name="wrist_angle">
      <hardwareInterface>hardware_interface/EffortJointInterface</hardwareInterface>
    </joint>
    <actuator name="wrist_angle_motor">
      <mechanicalReduction>1</mechanicalReduction>
    </actuator>
  </transmission>

  <link name="$(arg robot_name)/wrist_link">
    <visual>
      <origin rpy="0 ${pi} ${pi/2}" xyz="0 0 0"/>
      <geometry>
        <mesh filename="package://interbotix_descriptions/meshes/meshes_rx200/RXA-200-M-5-Wrist.stl" scale="0.001 0.001 0.001"/>
      </geometry>
      <material name="interbotix_black"/>
    </visual>
    <collision>
      <origin rpy="0 ${pi} ${pi/2}" xyz="0 0 0"/>
      <geometry>
        <mesh filename="package://interbotix_descriptions/meshes/meshes_rx200/RXA-200-M-5-Wrist.stl" scale="0.001 0.001 0.001"/>
      </geometry>
    </collision>
    <inertial>
      <origin rpy="0 ${pi} ${pi/2}" xyz="0.0423600000 0.0000104110 -0.0105770000"/>
      <mass value="0.084957" />
      <inertia ixx="0.0000308200" iyy="0.0000282200" izz="0.0000315200" ixy="0.0000000191" ixz="0.0000000023" iyz="0.0000025481" />
    </inertial>
  </link>

  <joint name="wrist_rotate" type="revolute">
    <axis xyz="1 0 0"/>
    <limit effort="100" lower="${-pi}" upper="${pi}" velocity="${pi}"/>
    <origin rpy="${-pi} 0 0" xyz="0.065 0 0"/>
    <parent link="$(arg robot_name)/wrist_link"/>
    <child link="$(arg robot_name)/gripper_link"/>
  </joint>

  <transmission name="trans_wrist_rotate">
    <type>transmission_interface/SimpleTransmission</type>
    <joint name="wrist_rotate">
      <hardwareInterface>hardware_interface/EffortJointInterface</hardwareInterface>
    </joint>
    <actuator name="wrist_rotate_motor">
      <mechanicalReduction>1</mechanicalReduction>
    </actuator>
  </transmission>

  <link name="$(arg robot_name)/gripper_link">
    <visual>
      <origin rpy="0 0 ${pi/2}" xyz="-0.02 0 0"/>
      <geometry>
        <mesh filename="package://interbotix_descriptions/meshes/meshes_rx200/RXA-200-M-6-Gripper.stl" scale="0.001 0.001 0.001"/>
      </geometry>
      <material name="interbotix_black"/>
    </visual>
    <collision>
      <origin rpy="0 0 ${pi/2}" xyz="-0.02 0 0"/>
      <geometry>
        <mesh filename="package://interbotix_descriptions/meshes/meshes_rx200/RXA-200-M-6-Gripper.stl" scale="0.001 0.001 0.001"/>
      </geometry>
    </collision>
    <inertial>
      <origin rpy="0 0 ${pi/2}" xyz="0.0216300000 0.0000000000 0.0114100000"/>
      <mass value="0.072885" />
      <inertia ixx="0.0000253700" iyy="0.0000183600" izz="0.0000167400" ixy="0.0000000000" ixz="0.0000000000" iyz="0.0000004340" />
    </inertial>
  </link>

  <joint name="ee_arm" type="fixed">
    <axis xyz="1 0 0"/>
    <origin rpy="0 0 0" xyz="0.043 0 0"/>
    <parent link="$(arg robot_name)/gripper_link"/>
    <child link="$(arg robot_name)/ee_arm_link"/>
  </joint>

  <link name="$(arg robot_name)/ee_arm_link">
    <inertial>
      <mass value="0.001" />
      <inertia ixx="0.001" iyy="0.001" izz="0.001" ixy="0" ixz="0" iyz="0" />
    </inertial>
  </link>

  <joint name="gripper" type="continuous">
    <axis xyz="1 0 0"/>
    <limit effort="100" velocity="${pi}"/>
    <origin rpy="0 0 0" xyz="0.0055 0 0"/>
    <parent link="$(arg robot_name)/ee_arm_link"/>
    <child link="$(arg robot_name)/gripper_prop_link"/>
  </joint>

  <transmission name="trans_gripper">
    <type>transmission_interface/SimpleTransmission</type>
    <joint name="gripper">
      <hardwareInterface>hardware_interface/EffortJointInterface</hardwareInterface>
    </joint>
    <actuator name="gripper_motor">
      <mechanicalReduction>1</mechanicalReduction>
    </actuator>
  </transmission>

  <link name="$(arg robot_name)/gripper_prop_link">
    <visual>
      <origin rpy="0 0 ${pi/2}" xyz="-0.0685 0 0"/>
      <geometry>
        <mesh filename="package://interbotix_descriptions/meshes/meshes_rx200/RXA-200-M-7-Gripper-Prop.stl" scale="0.001 0.001 0.001"/>
      </geometry>
      <material name="interbotix_black"/>
    </visual>
    <collision>
      <origin rpy="0 0 ${pi/2}" xyz="-0.0685 0 0"/>
      <geometry>
        <mesh filename="package://interbotix_descriptions/meshes/meshes_rx200/RXA-200-M-7-Gripper-Prop.stl" scale="0.001 0.001 0.001"/>
      </geometry>
    </collision>
    <inertial>
      <origin rpy="0 0 ${pi/2}" xyz="0.0008460000 -0.0000019330 0.0000420000"/>
      <mass value="0.00434" />
      <inertia ixx="0.0000005923" iyy="0.0000011156" izz="0.0000005743" ixy="0.0000000000" ixz="0.0000003195" iyz="-0.0000000004" />
    </inertial>
  </link>

  <!-- If the default gripper bar is being used, then also add the gripper bar -->

  <xacro:if value="$(arg use_default_gripper_bar)">

    <joint name="gripper_bar" type="fixed">
      <axis xyz="1 0 0"/>
      <origin rpy="0 0 0" xyz="0 0 0"/>
      <parent link="$(arg robot_name)/ee_arm_link"/>
      <child link="$(arg robot_name)/gripper_bar_link"/>
    </joint>

    <link name="$(arg robot_name)/gripper_bar_link">
      <visual>
        <origin rpy="0 0 ${pi/2}" xyz="-0.063 0 0"/>
        <geometry>
          <mesh filename="package://interbotix_descriptions/meshes/meshes_rx200/RXA-200-M-8-Gripper-Bar.stl" scale="0.001 0.001 0.001"/>
        </geometry>
        <material name="interbotix_black"/>
      </visual>
      <collision>
        <origin rpy="0 0 ${pi/2}" xyz="-0.063 0 0"/>
        <geometry>
          <mesh filename="package://interbotix_descriptions/meshes/meshes_rx200/RXA-200-M-8-Gripper-Bar.stl" scale="0.001 0.001 0.001"/>
        </geometry>
      </collision>
      <inertial>
        <origin rpy="0 0 ${pi/2}" xyz="0.0096870000 0.0000005660 0.0049620000"/>
        <mass value="0.034199" />
        <inertia ixx="0.0000074125" iyy="0.0000284300" izz="0.0000286000" ixy="-0.0000000008" ixz="-0.0000000006" iyz="-0.0000013889" />
      </inertial>
    </link>

    <joint name="ee_bar" type="fixed">
      <axis xyz="1 0 0"/>
      <origin rpy="0 0 0" xyz="0.023 0 0"/>
      <parent link="$(arg robot_name)/gripper_bar_link"/>
      <child link="$(arg robot_name)/fingers_link"/>
    </joint>

    <link name="$(arg robot_name)/fingers_link">
      <inertial>
        <mass value="0.001" />
        <inertia ixx="0.001" iyy="0.001" izz="0.001" ixy="0" ixz="0" iyz="0" />
      </inertial>
    </link>

    <!-- If the default gripper fingers are being used, add those as well -->

    <xacro:if value="$(arg use_default_gripper_fingers)">

      <joint name="left_finger" type="prismatic">
        <axis xyz="0 1 0"/>
        <limit effort="10" lower="0.015" upper="0.037" velocity="1"/>
        <origin rpy="0 0 0" xyz="0 0 0"/>
        <parent link="$(arg robot_name)/fingers_link"/>
        <child link="$(arg robot_name)/left_finger_link"/>
      </joint>

      <transmission name="trans_left_finger">
        <type>transmission_interface/SimpleTransmission</type>
        <joint name="left_finger">
          <hardwareInterface>hardware_interface/EffortJointInterface</hardwareInterface>
        </joint>
        <actuator name="left_finger_motor">
          <mechanicalReduction>1</mechanicalReduction>
        </actuator>
      </transmission>

      <link name="$(arg robot_name)/left_finger_link">
        <visual>
          <origin rpy="${pi} ${pi} 0" xyz="0 0.005 0"/>
          <geometry>
            <mesh filename="package://interbotix_descriptions/meshes/meshes_rx200/RXA-200-M-9-Finger.stl" scale="0.001 0.001 0.001"/>
          </geometry>
          <material name="interbotix_black"/>
        </visual>
        <collision>
          <origin rpy="${pi} ${pi} 0" xyz="0 0.005 0"/>
          <geometry>
            <mesh filename="package://interbotix_descriptions/meshes/meshes_rx200/RXA-200-M-9-Finger.stl" scale="0.001 0.001 0.001"/>
          </geometry>
        </collision>
        <inertial>
          <origin rpy="${pi} ${pi} ${pi/2}" xyz="0.0138160000 0.0000000000 0.0000000000"/>
           <mass value="0.016246" />
          <inertia ixx="0.0000047310" iyy="0.0000015506" izz="0.0000037467" ixy="-0.0000004560" ixz="0.0000000000" iyz="0.0000000000" />
        </inertial>
      </link>

      <joint name="right_finger" type="prismatic">
        <axis xyz="0 1 0"/>
        <limit effort="10" lower="-0.037" upper="-0.015" velocity="1"/>
        <origin rpy="0 0 0" xyz="0 0 0"/>
        <parent link="$(arg robot_name)/fingers_link"/>
        <child link="$(arg robot_name)/right_finger_link"/>
        <xacro:unless value="$(arg load_gazebo_configs)">
          <mimic joint="left_finger" multiplier="-1" offset="0"/>
        </xacro:unless>
      </joint>

      <transmission name="trans_right_finger">
        <type>transmission_interface/SimpleTransmission</type>
        <joint name="right_finger">
          <hardwareInterface>hardware_interface/EffortJointInterface</hardwareInterface>
        </joint>
        <actuator name="right_finger_motor">
          <mechanicalReduction>1</mechanicalReduction>
        </actuator>
      </transmission>

      <link name="$(arg robot_name)/right_finger_link">
        <visual>
          <origin rpy="0 ${pi} 0" xyz="0 -0.005 0"/>
          <geometry>
            <mesh filename="package://interbotix_descriptions/meshes/meshes_rx200/RXA-200-M-9-Finger.stl" scale="0.001 0.001 0.001"/>
          </geometry>
          <material name="interbotix_black"/>
        </visual>
        <collision>
          <origin rpy="0 ${pi} 0" xyz="0 -0.005 0"/>
          <geometry>
            <mesh filename="package://interbotix_descriptions/meshes/meshes_rx200/RXA-200-M-9-Finger.stl" scale="0.001 0.001 0.001"/>
          </geometry>
        </collision>
        <inertial>
          <origin rpy="0 ${pi} ${pi/2}" xyz="0.0138160000 0.0000000000  0.0000000000"/>
          <mass value="0.016246" />
          <inertia ixx="0.0000047310" iyy="0.0000015506" izz="0.0000037467" ixy="0.0000004560" ixz="0.0000000000" iyz="0.0000000000" />
        </inertial>
      </link>

      <joint name="ee_gripper" type="fixed">
        <axis xyz="1 0 0"/>
        <origin rpy="0 0 0" xyz="0.027575 0 0"/>
        <parent link="$(arg robot_name)/fingers_link"/>
        <child link="$(arg robot_name)/ee_gripper_link"/>
      </joint>

      <link name="$(arg robot_name)/ee_gripper_link">
        <inertial>
          <mass value="0.001" />
          <inertia ixx="0.001" iyy="0.001" izz="0.001" ixy="0" ixz="0" iyz="0" />
        </inertial>
      </link>

    </xacro:if>

  </xacro:if>

  <xacro:if value="${urdf_loc != ''}">
    <xacro:include filename="${urdf_loc}"/>
  </xacro:if>

</robot>
